Workbook

Sheet Inputs
A1: INPUTS CENTRALIZADOS — UVG Admon. Proyectos TI
A3: 1. Parámetros del proyecto
A4: Cantidad total de personas (Scrum/Scrumban/Kanban) | B4: 5
A5: Cantidad total de personas (XP + Scrumban) | B5: 6
A6: Cantidad total de épicas | B6: 6
A7: Cantidad total de historias | B7: 32
A8: Cantidad total de puntos de historia | B8: 121
A9: Cantidad total de tareas | B9: 133
A10: Tiempo de duración atómica sprint (días) | B10: 10
A11: Días laborales por mes | B11: 20
A12: Holgura estándar (Scrum/Kanban/Scrumban) | B12: 0.25
A13: Holgura XP + Scrumban | B13: 0.1
A14: Porcentaje de ganancia (margen) estándar | B14: 0.35
A15: Porcentaje de ganancia (margen) XP | B15: 0.35
... A17: PROM (porción Run reactiva) | B17: 0.2
A20: 2. Equipo cliente (Scrum / Kanban / Scrumban)
A21: Rol | B21: FTE | C21: Salario mensual | D21: Costo mensual
A22: Product Owner | B22: 1 | C22: 15000 | D22: =B22*C22 -> 15000
A23: Scrum Master | B23: 1 | C23: 13500 | D23: =B23*C23 -> 13500
A24: Developer Senior | B24: 1 | C24: 12904 | D24: =B24*C24 -> 12904
A25: Developer Senior | B25: 1 | C25: 12904 | D25: =B25*C25 -> 12904
A26: Developer Senior | B26: 1 | C26: 12904 | D26: =B26*C26 -> 12904
A27: Suma costo mensual cliente | D27: =SUM(D22:D26) -> 67212
A29: 3. Equipo interno (Scrum / Kanban / Scrumban)
A30: Rol | B30: FTE | C30: Salario mensual | D30: Costo mensual
A31: Product Owner | B31: 0.7 | C31: 15000 | D31: =B31*C31 -> 10500
A32: Scrum Master | B32: 1 | C32: 13500 | D32: =B32*C32 -> 13500
A33: Developer Senior | B33: 1 | C33: 12904 | D33: =B33*C33 -> 12904
A34: Developer Senior | B34: 1 | C34: 12904 | D34: =B34*C34 -> 12904
A35: Developer Senior | B35: 1 | C35: 12904 | D35: =B35*C35 -> 12904
A36: Suma costo mensual interno | D36: =SUM(D31:D35) -> 62712
A38: 4. Equipo XP + Scrumban (cliente)
A39: Rol | B39: FTE | C39: Salario mensual | D39: Costo mensual
A40: Coach | B40: 1 | C40: 15000 | D40: =B40*C40 -> 15000
A41: Tracker / Tester | B41: 1 | C41: 13500 | D41: =B41*C41 -> 13500
A42: Developer Senior | B42: 1 | C42: 12904 | D42: =B42*C42 -> 12904
A43: Developer Senior | B43: 1 | C43: 12904 | D43: =B43*C43 -> 12904
A44: Developer Junior | B44: 1 | C44: 9000 | D44: =B44*C44 -> 9000
A45: Developer Junior | B45: 1 | C45: 9000 | D45: =B45*C45 -> 9000
A46: Suma costo mensual XP cliente | D46: =SUM(D40:D45) -> 72308
...

Sheet Scrum
A1: Cálculo de costos — Scrum
A3: Vista cliente | D3: Vista interno
A4: Concepto | B4: Valor | D4: Concepto | E4: Valor
A5: Burn rate mensual | B5: =Inputs!$D$27 -> 67212 | D5: Burn rate mensual | E5: =Inputs!$D$36 -> 62712
A6: Velocidad promedio (SP/sprint) | B6: =ROUNDDOWN(Inputs!$B$8/Inputs!$B$6,0) -> 20 | D6: Velocidad promedio (SP/sprint) | E6: =ROUNDDOWN(Inputs!$B$8/Inputs!$B$6,0) -> 20
A7: Cantidad de sprints necesarios | B7: =ROUNDUP(Inputs!$B$8/B6,0) -> 7 | D7: Cantidad de sprints necesarios | E7: =ROUNDUP(Inputs!$B$8/E6,0) -> 7
A8: Cantidad de sprints con buffer | B8: =ROUNDUP(B7*(1+Inputs!$B$12),0) -> 9 | D8: Cantidad de sprints con buffer | E8: =ROUNDUP(E7*(1+Inputs!$B$12),0) -> 9
A9: Duración estimada (días) | B9: =B7*Inputs!$B$10 -> 70 | D9: Duración estimada (días) | E9: =E7*Inputs!$B$10 -> 70
A10: Duración con buffer (días) | B10: =B8*Inputs!$B$10 -> 90 | D10: Duración con buffer (días) | E10: =E8*Inputs!$B$10 -> 90
A11: Costo por sprint | B11: =B5*(Inputs!$B$10/Inputs!$B$11) -> 33606 | D11: Costo por sprint | E11: =E5*(Inputs!$B$10/Inputs!$B$11) -> 31356
A12: Costo equipo del proyecto | B12: =B11*B7 -> 235242 | D12: Costo equipo del proyecto | E12: =E11*E7 -> 219492
A13: Costo equipo (con buffer) | B13: =B11*B8 -> 302454 | D13: Costo equipo (con buffer) | E13: =E11*E8 -> 282204
A15: Cálculo del precio cliente (patrón curso)
A16: Concepto | B16: Vista cliente | D16: Concepto | E16: Vista interno
A17: Costo equipo (con buffer) | B17: =B13 -> 302454 | D17: Costo equipo (con buffer) | E17: =E13 -> 282204
A18: (+) Costos adicionales | B18: ='Costos adicionales'!$B$12 -> 105870 | D18: (+) Costos adicionales | E18: ='Costos adicionales'!$B$12 -> 105870
A19: (+) Reserva de riesgos (Σ EMV) | B19: =Riesgos!$J$13 -> 133769.8 | D19: (+) Reserva de riesgos (Σ EMV) | E19: =Riesgos!$J$13 -> 133769.8
A20: (=) Presupuesto con riesgos (inversión) | B20: =B17+B18+B19 -> 542093.8 | D20: (=) Presupuesto con riesgos (inversión) | E20: =E17+E18+E19 -> 521843.8
A21: Margen de ganancia (entrada) | B21: =Inputs!$B$14 -> 0.35 | D21: Margen de ganancia (entrada) | E21: =Inputs!$B$14 -> 0.35
A22: Precio cliente = Inversión/(1-margen) | B22: =B20/(1-B21) -> 833990.46 | D22: Precio cliente = Inversión/(1-margen) | E22: =E20/(1-E21) -> 802836.62
A23: Precio cliente redondeado (CEILING 1000) | B23: =ROUNDUP(B22,-3) -> 834000 | D23: Precio cliente redondeado (CEILING 1000) | E23: =ROUNDUP(E22,-3) -> 803000
A24: Beneficio neto = Precio − Inversión | B24: =B22-B20 -> 291896.66 | D24: Beneficio neto = Precio − Inversión | E24: =E22-E20 -> 280992.82
A25: ROI = Beneficio neto / Inversión | B25: =B24/B20 -> 0.53846154 | D25: ROI = Beneficio neto / Inversión | E25: =E24/E20 -> 0.53846154
A26: Margen bruto absoluto (Precio − Costo) | B26: =B22-B20 -> 291896.66 | D26: Margen bruto absoluto (Precio − Costo) | E26: =E22-E20 -> 280992.82
A27: Margen bruto % (inversa) | B27: =B26/B22 -> 0.35 | D27: Margen bruto % (inversa) | E27: =E26/E22 -> 0.35

Sheet Kanban
A1: Cálculo de costos — Kanban
A3: Vista cliente | D3: Vista interno
A4: Concepto | B4: Valor | D4: Concepto | E4: Valor
A5: Burn rate mensual | B5: =Inputs!$D$27 -> 67212 | D5: Burn rate mensual | E5: =Inputs!$D$36 -> 62712
A6: Días totales de tareas | B6: =Inputs!$B$59 -> 682 | D6: Días totales de tareas | E6: =Inputs!$B$59 -> 682
A7: Número de ejecutores | B7: =Inputs!$B$60 -> 4 | D7: Número de ejecutores | E7: =Inputs!$B$60 -> 4
A8: Cycle Time promedio (días/tarea) | B8: =B6/Inputs!$B$9 -> 5.1278195 | D8: Cycle Time promedio (días/tarea) | E8: =E6/Inputs!$B$9 -> 5.1278195
A9: Throughput diario (tareas/día) | B9: =B7/B8 -> 0.78005865 | D9: Throughput diario (tareas/día) | E9: =E7/E8 -> 0.78005865
A10: Throughput mensual | B10: =B9*Inputs!$B$11 -> 15.601173 | D10: Throughput mensual | E10: =E9*Inputs!$B$11 -> 15.601173
A11: Días operativos | B11: =ROUNDUP(Inputs!$B$9/B9,0) -> 171 | D11: Días operativos | E11: =ROUNDUP(Inputs!$B$9/E9,0) -> 171
A12: Meses totales | B12: =ROUNDUP(B11/Inputs!$B$11,0) -> 9 | D12: Meses totales | E12: =ROUNDUP(E11/Inputs!$B$11,0) -> 9
A13: Días operativos (buffer) | B13: =ROUNDUP(B11*(1+Inputs!$B$12),0) -> 214 | D13: Días operativos (buffer) | E13: =ROUNDUP(E11*(1+Inputs!$B$12),0) -> 214
A14: Meses totales (buffer) | B14: =ROUNDUP(B13/Inputs!$B$11,0) -> 11 | D14: Meses totales (buffer) | E14: =ROUNDUP(E13/Inputs!$B$11,0) -> 11
A15: Costo equipo del proyecto | B15: =B5*B12 -> 604908 | D15: Costo equipo del proyecto | E15: =E5*E12 -> 564408
A16: Costo equipo (con buffer) | B16: =B5*B14 -> 739332 | D16: Costo equipo (con buffer) | E16: =E5*E14 -> 689832
A18: Cálculo del precio cliente (patrón curso)
A19: Concepto | B19: Vista cliente | D19: Concepto | E19: Vista interno
A20: Costo equipo (con buffer) | B20: =B16 -> 739332 | D20: Costo equipo (con buffer) | E20: =E16 -> 689832
A21: (+) Costos adicionales | B21: ='Costos adicionales'!$B$24 -> 160740 | D21: (+) Costos adicionales | E21: ='Costos adicionales'!$B$24 -> 160740
A22: (+) Reserva de riesgos (Σ EMV) | B22: =Riesgos!$J$13 -> 133769.8 | D22: (+) Reserva de riesgos (Σ EMV) | E22: =Riesgos!$J$13 -> 133769.8
A23: (=) Presupuesto con riesgos (inversión) | B23: =B20+B21+B22 -> 1033841.8 | D23: (=) Presupuesto con riesgos (inversión) | E23: =E20+E21+E22 -> 984341.8
A24: Margen de ganancia (entrada) | B24: =Inputs!$B$14 -> 0.35 | D24: Margen de ganancia (entrada) | E24: =Inputs!$B$14 -> 0.35
A25: Precio cliente = Inversión/(1-margen) | B25: =B23/(1-B24) -> 1590525.8 | D25: Precio cliente = Inversión/(1-margen) | E25: =E23/(1-E24) -> 1514372
A26: Precio cliente redondeado (CEILING 1000) | B26: =ROUNDUP(B25,-3) -> 1591000 | D26: Precio cliente redondeado (CEILING 1000) | E26: =ROUNDUP(E25,-3) -> 1515000
A27: Beneficio neto = Precio − Inversión | B27: =B25-B23 -> 556684.05 | D27: Beneficio neto = Precio − Inversión | E27: =E25-E23 -> 530030.2
A28: ROI = Beneficio neto / Inversión | B28: =B27/B23 -> 0.53846154 | D28: ROI = Beneficio neto / Inversión | E28: =E27/E23 -> 0.53846154
A29: Margen bruto absoluto (Precio − Costo) | B29: =B25-B23 -> 556684.05 | D29: Margen bruto absoluto (Precio − Costo) | E29: =E25-E23 -> 530030.2
A30: Margen bruto % (inversa) | B30: =B29/B25 -> 0.35 | D30: Margen bruto % (inversa) | E30: =E29/E25 -> 0.35

Sheet Scrumban
A1: Cálculo de costos — Scrumban
A3: Vista cliente | D3: Vista interno
A4: Concepto | B4: Valor | D4: Concepto | E4: Valor
A5: Burn rate mensual | B5: =Inputs!$D$27 -> 67212 | D5: Burn rate mensual | E5: =Inputs!$D$36 -> 62712
A6: Velocidad promedio (SP/sprint) | B6: =ROUNDDOWN(Inputs!$B$8/Inputs!$B$6,0) -> 20 | D6: Velocidad promedio (SP/sprint) | E6: =ROUNDDOWN(Inputs!$B$8/Inputs!$B$6,0) -> 20
A7: Cantidad de sprints necesarios | B7: =ROUNDUP(Inputs!$B$8/B6,0) -> 7 | D7: Cantidad de sprints necesarios | E7: =ROUNDUP(Inputs!$B$8/E6,0) -> 7
A8: Cantidad de sprints con buffer | B8: =ROUNDUP(B7*(1+Inputs!$B$12),0) -> 9 | D8: Cantidad de sprints con buffer | E8: =ROUNDUP(E7*(1+Inputs!$B$12),0) -> 9
A9: Duración estimada (días) | B9: =B7*Inputs!$B$10 -> 70 | D9: Duración estimada (días) | E9: =E7*Inputs!$B$10 -> 70
A10: Duración con buffer (días) | B10: =B8*Inputs!$B$10 -> 90 | D10: Duración con buffer (días) | E10: =E8*Inputs!$B$10 -> 90
A11: Costo por sprint | B11: =B5*(Inputs!$B$10/Inputs!$B$11) -> 33606 | D11: Costo por sprint | E11: =E5*(Inputs!$B$10/Inputs!$B$11) -> 31356
A12: Costo equipo del proyecto | B12: =B11*B7 -> 235242 | D12: Costo equipo del proyecto | E12: =E11*E7 -> 219492
A13: Costo equipo (con buffer) | B13: =B11*B8 -> 302454 | D13: Costo equipo (con buffer) | E13: =E11*E8 -> 282204
A15: Desglose BID / ROM (Scrumban)
A16: Concepto | B16: Valor cliente | D16: Concepto | E16: Valor interno
A17: PBID (80 %) | B17: =Inputs!$B$16 -> 0.8 | D17: PBID (80 %) | E17: =Inputs!$B$16 -> 0.8
A18: PROM (20 %) | B18: =Inputs!$B$17 -> 0.2 | D18: PROM (20 %) | E18: =Inputs!$B$17 -> 0.2
A19: Costo por sprint BID | B19: =B11*Inputs!$B$16 -> 26884.8 | D19: Costo por sprint BID | E19: =E11*Inputs!$B$16 -> 25084.8
A20: Costo por sprint ROM | B20: =B11*Inputs!$B$17 -> 6721.2 | D20: Costo por sprint ROM | E20: =E11*Inputs!$B$17 -> 6271.2
A22: Cálculo del precio cliente (patrón curso)
A23: Concepto | B23: Vista cliente | D23: Concepto | E23: Vista interno
A24: Costo equipo (con buffer) | B24: =B13 -> 302454 | D24: Costo equipo (con buffer) | E24: =E13 -> 282204
A25: (+) Costos adicionales | B25: ='Costos adicionales'!$B$12 -> 105870 | D25: (+) Costos adicionales | E25: ='Costos adicionales'!$B$12 -> 105870
A26: (+) Reserva de riesgos (Σ EMV) | B26: =Riesgos!$J$13 -> 133769.8 | D26: (+) Reserva de riesgos (Σ EMV) | E26: =Riesgos!$J$13 -> 133769.8
A27: (=) Presupuesto con riesgos (inversión) | B27: =B24+B25+B26 -> 542093.8 | D27: (=) Presupuesto con riesgos (inversión) | E27: =E24+E25+E26 -> 521843.8
A28: Margen de ganancia (entrada) | B28: =Inputs!$B$14 -> 0.35 | D28: Margen de ganancia (entrada) | E28: =Inputs!$B$14 -> 0.35
A29: Precio cliente = Inversión/(1-margen) | B29: =B27/(1-B28) -> 833990.46 | D29: Precio cliente = Inversión/(1-margen) | E29: =E27/(1-E28) -> 802836.62
A30: Precio cliente redondeado (CEILING 1000) | B30: =ROUNDUP(B29,-3) -> 834000 | D30: Precio cliente redondeado (CEILING 1000) | E30: =ROUNDUP(E29,-3) -> 803000
A31: Beneficio neto = Precio − Inversión | B31: =B29-B27 -> 291896.66 | D31: Beneficio neto = Precio − Inversión | E31: =E29-E27 -> 280992.82
A32: ROI = Beneficio neto / Inversión | B32: =B31/B27 -> 0.53846154 | D32: ROI = Beneficio neto / Inversión | E32: =E31/E27 -> 0.53846154
A33: Margen bruto absoluto (Precio − Costo) | B33: =B29-B27 -> 291896.66 | D33: Margen bruto absoluto (Precio − Costo) | E33: =E29-E27 -> 280992.82
A34: Margen bruto % (inversa) | B34: =B33/B29 -> 0.35 | D34: Margen bruto % (inversa) | E34: =E33/E29 -> 0.35

Sheet XP + Scrumban
A1: Cálculo de costos — XP + Scrumban
A3: Vista cliente | D3: Vista interno
A4: Concepto | B4: Valor | D4: Concepto | E4: Valor
A5: Burn rate mensual | B5: =Inputs!$D$46 -> 72308 | D5: Burn rate mensual | E5: =Inputs!$D$56 -> 67808
A6: Velocidad promedio (SP/sprint) | B6: =ROUNDDOWN(Inputs!$B$8/Inputs!$B$6,0) -> 20 | D6: Velocidad promedio (SP/sprint) | E6: =ROUNDDOWN(Inputs!$B$8/Inputs!$B$6,0) -> 20
A7: Cantidad de sprints necesarios | B7: =ROUNDUP(Inputs!$B$8/B6,0) -> 7 | D7: Cantidad de sprints necesarios | E7: =ROUNDUP(Inputs!$B$8/E6,0) -> 7
A8: Cantidad de sprints con buffer | B8: =ROUNDUP(B7*(1+Inputs!$B$13),0) -> 8 | D8: Cantidad de sprints con buffer | E8: =ROUNDUP(E7*(1+Inputs!$B$13),0) -> 8
A9: Duración estimada (días) | B9: =B7*Inputs!$B$10 -> 70 | D9: Duración estimada (días) | E9: =E7*Inputs!$B$10 -> 70
A10: Duración con buffer (días) | B10: =B8*Inputs!$B$10 -> 80 | D10: Duración con buffer (días) | E10: =E8*Inputs!$B$10 -> 80
A11: Costo por sprint | B11: =B5*(Inputs!$B$10/Inputs!$B$11) -> 36154 | D11: Costo por sprint | E11: =E5*(Inputs!$B$10/Inputs!$B$11) -> 33904
A12: Costo equipo del proyecto | B12: =B11*B7 -> 253078 | D12: Costo equipo del proyecto | E12: =E11*E7 -> 237328
A13: Costo equipo (con buffer) | B13: =B11*B8 -> 289232 | D13: Costo equipo (con buffer) | E13: =E11*E8 -> 271232
A15: Desglose BID / ROM (Scrumban)
A16: Concepto | B16: Valor cliente | D16: Concepto | E16: Valor interno
A17: PBID (80 %) | B17: =Inputs!$B$16 -> 0.8 | D17: PBID (80 %) | E17: =Inputs!$B$16 -> 0.8
A18: PROM (20 %) | B18: =Inputs!$B$17 -> 0.2 | D18: PROM (20 %) | E18: =Inputs!$B$17 -> 0.2
A19: Costo por sprint BID | B19: =B11*Inputs!$B$16 -> 28923.2 | D19: Costo por sprint BID | E19: =E11*Inputs!$B$16 -> 27123.2
A20: Costo por sprint ROM | B20: =B11*Inputs!$B$17 -> 7230.8 | D20: Costo por sprint ROM | E20: =E11*Inputs!$B$17 -> 6780.8
A22: Cálculo del precio cliente (patrón curso)
A23: Concepto | B23: Vista cliente | D23: Concepto | E23: Vista interno
A24: Costo equipo (con buffer) | B24: =B13 -> 289232 | D24: Costo equipo (con buffer) | E24: =E13 -> 271232
A25: (+) Costos adicionales | B25: ='Costos adicionales'!$B$12 -> 105870 | D25: (+) Costos adicionales | E25: ='Costos adicionales'!$B$12 -> 105870
A26: (+) Reserva de riesgos (Σ EMV) | B26: =Riesgos!$J$13 -> 133769.8 | D26: (+) Reserva de riesgos (Σ EMV) | E26: =Riesgos!$J$13 -> 133769.8
A27: (=) Presupuesto con riesgos (inversión) | B27: =B24+B25+B26 -> 528871.8 | D27: (=) Presupuesto con riesgos (inversión) | E27: =E24+E25+E26 -> 510871.8
A28: Margen de ganancia (entrada) | B28: =Inputs!$B$15 -> 0.35 | D28: Margen de ganancia (entrada) | E28: =Inputs!$B$15 -> 0.35
A29: Precio cliente = Inversión/(1-margen) | B29: =B27/(1-B28) -> 813648.92 | D29: Precio cliente = Inversión/(1-margen) | E29: =E27/(1-E28) -> 785956.62
A30: Precio cliente redondeado (CEILING 1000) | B30: =ROUNDUP(B29,-3) -> 814000 | D30: Precio cliente redondeado (CEILING 1000) | E30: =ROUNDUP(E29,-3) -> 786000
A31: Beneficio neto = Precio − Inversión | B31: =B29-B27 -> 284777.12 | D31: Beneficio neto = Precio − Inversión | E31: =E29-E27 -> 275084.82
A32: ROI = Beneficio neto / Inversión | B32: =B31/B27 -> 0.53846154 | D32: ROI = Beneficio neto / Inversión | E32: =E31/E27 -> 0.53846154
A33: Margen bruto absoluto (Precio − Costo) | B33: =B29-B27 -> 284777.12 | D33: Margen bruto absoluto (Precio − Costo) | E33: =E29-E27 -> 275084.82
A34: Margen bruto % (inversa) | B34: =B33/B29 -> 0.35 | D34: Margen bruto % (inversa) | E34: =E33/E29 -> 0.35

Sheet Margen bruto
A1: Margen bruto por metodología (debe coincidir con el margen de entrada)
A3: Metodología | B3: Precio cliente | C3: Inversión | D3: Margen bruto absoluto | E3: % Margen (inversa)
A4: Scrum | B4: =Scrum!B22 -> 833990.46 | C4: =Scrum!B20 -> 542093.8 | D4: =B4-C4 -> 291896.66 | E4: =D4/B4 -> 0.35
A5: Kanban | B5: =Kanban!B25 -> 1590525.8 | C5: =Kanban!B23 -> 1033841.8 | D5: =B5-C5 -> 556684.05 | E5: =D5/B5 -> 0.35
A6: Scrumban | B6: =Scrumban!B29 -> 833990.46 | C6: =Scrumban!B27 -> 542093.8 | D6: =B6-C6 -> 291896.66 | E6: =D6/B6 -> 0.35
A7: XP + Scrumban | B7: ='XP + Scrumban'!B29 -> 813648.92 | C7: ='XP + Scrumban'!B27 -> 528871.8 | D7: =B7-C7 -> 284777.12 | E7: =D7/B7 -> 0.35

Sheet ROI por metodología
A1: ROI por metodología vs TMAR (vista cliente — incluye costos adicionales y riesgos)
A3: Metodología | B3: Precio cliente | C3: Inversión (costo + adic + riesgos) | D3: Beneficio neto | E3: ROI | F3: TMAR | G3: ¿ROI > TMAR? | H3: Veredicto
A4: Scrum | B4: =Scrum!B22 -> 833990.46 | C4: =Scrum!B20 -> 542093.8 | D4: =B4-C4 -> 291896.66 | E4: =D4/C4 -> 0.53846154 | F4: =Inputs!$B$76 -> 0.35 | G4: =IF(E4>F4,"Sí","No") -> Sí | H4: =IF(E4>F4,"Proyecto financieramente atractivo","Replantearse / no conviene") -> Proyecto financieramente atractivo
A5: Kanban | B5: =Kanban!B25 -> 1590525.8 | C5: =Kanban!B23 -> 1033841.8 | D5: =B5-C5 -> 556684.05 | E5: =D5/C5 -> 0.53846154 | F5: =Inputs!$B$76 -> 0.35 | G5: =IF(E5>F5,"Sí","No") -> Sí | H5: =IF(E5>F5,"Proyecto financieramente atractivo","Replantearse / no conviene") -> Proyecto financieramente atractivo
A6: Scrumban | B6: =Scrumban!B29 -> 833990.46 | C6: =Scrumban!B27 -> 542093.8 | D6: =B6-C6 -> 291896.66 | E6: =D6/C6 -> 0.53846154 | F6: =Inputs!$B$76 -> 0.35 | G6: =IF(E6>F6,"Sí","No") -> Sí | H6: =IF(E6>F6,"Proyecto financieramente atractivo","Replantearse / no conviene") -> Proyecto financieramente atractivo
A7: XP + Scrumban | B7: ='XP + Scrumban'!B29 -> 813648.92 | C7: ='XP + Scrumban'!B27 -> 528871.8 | D7: =B7-C7 -> 284777.12 | E7: =D7/C7 -> 0.53846154 | F7: =Inputs!$B$76 -> 0.35 | G7: =IF(E7>F7,"Sí","No") -> Sí | H7: =IF(E7>F7,"Proyecto financieramente atractivo","Replantearse / no conviene") -> Proyecto financieramente atractivo

Sheet Riesgos
A1: Matriz de riesgos del proyecto
A3: ID | B3: Riesgo | C3: Tipo | D3: Probabilidad cual. | E3: Impacto cual. | F3: Nivel | G3: Probabilidad numérica | H3: Impacto (meses) | I3: Costo del riesgo (GTQ) | J3: EMV (GTQ) | K3: Mitigación | L3: Responsable
A4: R1 | B4: Cambios de requerimientos frecuentes por parte del cliente | C4: Alcance | D4: Media | E4: Alto | F4: Alto | G4: 0.4 | H4: 1 | I4: =(Inputs!$D$46)*H4 -> 72308 | J4: =G4*I4 -> 28923.2 | K4: DoR firme y control de cambios documentado por el Product Owner. | L4: Product Owner
A5: R2 | B5: Retraso técnico por dependencias de infraestructura cloud | C5: Tiempo | D5: Media | E5: Medio | F5: Medio | G5: 0.4 | H5: 0.5 | I5: =(Inputs!$D$46)*H5 -> 36154 | J5: =G5*I5 -> 14461.6 | K5: Entorno de pruebas paralelo desde Sprint 1; proveedor cloud con SLA definido. | L5: Developer líder
A6: R3 | B6: Falta de comunicación entre equipo y stakeholders | C6: Comunicación | D6: Baja | E6: Medio | F6: Medio | G6: 0.2 | H6: 0.5 | I6: =(Inputs!$D$46)*H6 -> 36154 | J6: =G6*I6 -> 7230.8 | K6: Canales formales (Slack + actas de Sprint Review). | L6: Scrum Master
A7: R4 | B7: Falta de involucramiento por parte del cliente | C7: Alcance | D7: Baja | E7: Alto | F7: Alto | G7: 0.2 | H7: 1 | I7: =(Inputs!$D$46)*H7 -> 72308 | J7: =G7*I7 -> 14461.6 | K7: Calendario fijo de validaciones quincenales con el cliente UVG. | L7: Scrum Master
A8: R5 | B8: Rotación o indisponibilidad temporal de un miembro del equipo | C8: Personal | D8: Baja | E8: Medio | F8: Medio | G8: 0.2 | H8: 0.5 | I8: =(Inputs!$D$46)*H8 -> 36154 | J8: =G8*I8 -> 7230.8 | K8: Documentación técnica continua y pair programming. | L8: Scrum Master
A9: R6 | B9: Falla o indisponibilidad del proveedor cloud | C9: Proveedor | D9: Baja | E9: Bajo | F9: Bajo | G9: 0.2 | H9: 0.25 | I9: =(Inputs!$D$46)*H9 -> 18077 | J9: =G9*I9 -> 3615.4 | K9: SLA contractual con penalidades; plan de contingencia en segundo proveedor. | L9: Product Owner
A10: R7 | B10: Baja adopción del sistema por estudiantes de diversificado | C10: Cliente / Usuario | D10: Media | E10: Alto | F10: Alto | G10: 0.4 | H10: 1 | I10: =(Inputs!$D$46)*H10 -> 72308 | J10: =G10*I10 -> 28923.2 | K10: Pruebas de usabilidad Sprint 8; comunicación con Dirección de Admisiones. | L10: Product Owner
A11: R8 | B11: Exposición o fuga de datos personales de estudiantes | C11: Técnico / Legal | D11: Baja | E11: Crítico | F11: Alto | G11: 0.2 | H11: 1.5 | I11: =(Inputs!$D$46)*H11 -> 108462 | J11: =G11*I11 -> 21692.4 | K11: Cifrado en tránsito y reposo, revisión de seguridad por sprint, NDA. | L11: Developer (seguridad)
A12: R9 | B12: Modificación del pensum UVG 2026 durante el desarrollo | C12: Alcance | D12: Baja | E12: Medio | F12: Medio | G12: 0.2 | H12: 0.5 | I12: =(Inputs!$D$46)*H12 -> 36154 | J12: =G12*I12 -> 7230.8 | K12: Catálogo de carreras actualizable sin rediseño del motor de recomendación. | L12: Product Owner
H13: Reserva de contingencia (Σ EMV) | J13: =SUM(J4:J12) -> 133769.8

Sheet Costos adicionales
A1: Costos adicionales (insumos / infraestructura)
F2: Constantes (mensual)
A3: Costos para 6 meses de desarrollo | F3: Insumo | G3: Valor mensual
A4: Insumo | B4: Valor total | F4: Suscripción Microsoft Office Business Standard (todos) | G4: 750
A5: Microsoft Office Business Standard (6 meses) | B5: =$G$4*6 -> 4500 | F5: Equipo de cómputo desarrollador (unidad) | G5: 13000
A6: Equipo de cómputo (3 dev + 2 ejecutivo, 1 vez) | B6: =($G$5*3)+($G$6*2) -> 51000 | F6: Equipo de cómputo cargo ejecutivo (unidad) | G6: 6000
A7: Claude Team Pro (6 meses) | B7: =$G$7*6 -> 4500 | F7: Suscripción Claude Team Pro (equipo) | G7: 750
A8: Internet residencial Tigo (6 meses) | B8: =$G$8*6 -> 13500 | F8: Internet residencial Tigo (todos) | G8: 2250
A9: Luz EEGSA (6 meses) | B9: =$G$9*6 -> 30000 | F9: Luz EEGSA 500 kWh | G9: 5000
A10: Google Colab Pro (6 meses) | B10: =$G$10*6 -> 1170 | F10: Licencia Google Colab Pro | G10: 195
A11: Infraestructura cloud (6 meses) | B11: =$G$11*6 -> 1200 | F11: Infraestructura cloud | G11: 200
A12: Total 6 meses | B12: =SUM(B5:B11) -> 105870
A15: Costos para 12 meses de desarrollo
A16: Insumo | B16: Valor total
A17: Microsoft Office Business Standard (12 meses) | B17: =$G$4*12 -> 9000
A18: Equipo de cómputo (3 dev + 2 ejecutivo, 1 vez) | B18: =($G$5*3)+($G$6*2) -> 51000
A19: Claude Team Pro (12 meses) | B19: =$G$7*12 -> 9000
A20: Internet residencial Tigo (12 meses) | B20: =$G$8*12 -> 27000
A21: Luz EEGSA (12 meses) | B21: =$G$9*12 -> 60000
A22: Google Colab Pro (12 meses) | B22: =$G$10*12 -> 2340
A23: Infraestructura cloud (12 meses) | B23: =$G$11*12 -> 2400
A24: Total 12 meses | B24: =SUM(B17:B23) -> 160740

Sheet TMAR
A1: TMAR — Tasa Mínima Aceptable de Rendimiento
A3: Composición
A4: Componente | B4: Valor | C4: Comentario
A5: Inflación anual | B5: =Inputs!$B$73 -> 0.05 | C5: El dinero se deprecia 5 % al año.
A6: Prima por riesgo del proyecto | B6: =Inputs!$B$74 -> 0.1 | C6: Proyecto de complejidad técnica intermedia.
A7: Rendimiento mínimo esperado | B7: =Inputs!$B$75 -> 0.2 | C7: Meta de la empresa proveedora.
A8: TMAR total | B8: =SUM(B5:B7) -> 0.35
A11: Tabla orientativa de riesgo
A12: Tipo de proyecto | B12: Riesgo sugerido | C12: Comentario
A13: Muy estable | B13: 3 % – 5 % | C13: Reemplazo de sistema con requisitos cerrados.
A14: Normal | B14: 6 % – 10 % | C14: Caso típico de proyecto interno.
A15: Muy riesgoso | B15: 12 % – 20 % | C15: Innovación, tecnología nueva, alta incertidumbre.

Sheet ROA
A1: ROA — Return on Assets (empresa proveedora)
A3: Activos de la empresa
A4: Activo | B4: Valor (GTQ)
A5: Laptops | B5: 120000
A6: Servidores | B6: 150000
A7: Licencias | B7: 30000
A8: Oficina / infraestructura | B8: 100000
A9: Equipo de testing | B9: 20000
A10: Mobiliario / redes | B10: 80000
A11: Total activos | B11: =SUM(B5:B10) -> 500000

Sheet Tareas (sin XP)
A1: Tareas (sin XP)
A2: Épica | B2: Historia de usuario | C2: Contenido | D2: Cantidad de días
A3: EP01 | B3: EP01-US01 | C3: Crear tabla de usuarios en base de datos. | D3: 4
A4: EP01 | B4: EP01-US01 | C4: Crear endpoint para registro de usuario. | D4: 5
A5: EP01 | B5: EP01-US01 | C5: Implementar hashing seguro de contraseña. | D5: 5
A6: EP01 | B6: EP01-US01 | C6: Diseñar pantalla de registro. | D6: 4
A7: EP01 | B7: EP01-US01 | C7: Implementar formulario de registro con validaciones. | D7: 5
A8: EP01 | B8: EP01-US01 | C8: Implementar pantalla de confirmación de registro exitoso. | D8: 4
A9: EP01 | B9: EP01-US02 | C9: Crear tabla de perfil académico en base de datos. | D9: 4
A10: EP01 | B10: EP01-US02 | C10: Crear endpoints para guardar y actualizar información académica. | D10: 5
A11: EP01 | B11: EP01-US02 | C11: Implementar validaciones de campos del perfil académico. | D11: 4
A12: EP01 | B12: EP01-US02 | C12: Diseñar sección de perfil académico. | D12: 4
A13: EP01 | B13: EP01-US02 | C13: Implementar formulario de perfil académico con validaciones. | D13: 5
A14: EP01 | B14: EP01-US03 | C14: Crear tabla de experiencias en base de datos. | D14: 4
... A135: EP06 | B135: EP06-US06 | C135: Diseñar una interfaz de administración que muestre los perfiles y sus características principales. | D135: 6
C136: Total días | D136: =SUM(D3:D135) -> 682

Sheet Tareas (con XP)
A1: Tareas (con XP)
A2: Épica | B2: Historia de usuario | C2: Contenido | D2: Cantidad de días
A3: EP01 | B3: EP01-US01 | C3: Crear tabla de usuarios en base de datos. | D3: 5
A4: EP01 | B4: EP01-US01 | C4: Crear endpoint para registro de usuario. | D4: 6
A5: EP01 | B5: EP01-US01 | C5: Implementar hashing seguro de contraseña. | D5: 6
A6: EP01 | B6: EP01-US01 | C6: Diseñar pantalla de registro. | D6: 5
A7: EP01 | B7: EP01-US01 | C7: Implementar formulario de registro con validaciones. | D7: 6
A8: EP01 | B8: EP01-US01 | C8: Implementar pantalla de confirmación de registro exitoso. | D8: 5
A9: EP01 | B9: EP01-US02 | C9: Crear tabla de perfil académico en base de datos. | D9: 5
A10: EP01 | B10: EP01-US02 | C10: Crear endpoints para guardar y actualizar información académica. | D10: 6
A11: EP01 | B11: EP01-US02 | C11: Implementar validaciones de campos del perfil académico. | D11: 5
A12: EP01 | B12: EP01-US02 | C12: Diseñar sección de perfil académico. | D12: 5
A13: EP01 | B13: EP01-US02 | C13: Implementar formulario de perfil académico con validaciones. | D13: 6
A14: EP01 | B14: EP01-US03 | C14: Crear tabla de experiencias en base de datos. | D14: 5
... A135: EP06 | B135: EP06-US06 | C135: Diseñar una interfaz de administración que muestre los perfiles y sus características principales. | D135: 7
C136: Total días | D136: =SUM(D3:D135) -> 815
